Workbook

Sheet Instructions
C1: Using the Status tracker
A3: At the end of each week, update the status of all activities completed during the week
A4: The status tracker shown in this worksheet is an example tracker (values filled are during the middle of the week)
A5: Fill in hours spent on each activity during the current week
B6: If 5 team members each spent an hour, that counts as 5 hours
B7: Fill in time for activities not fully completed ("ongoing") as well, then update these values during following weeks
A8: During the planning phases, identify the activities to be done during each week
A9: If you spend time on an activity not listed in the tracker, add the activity and list actual hours (need not fill in estimated hours if you didn't estimate it up front)
A11: For new activities, identify the type of activity - documentation, coordination, estimation etc.
A13: At the end of each week, plan ahead for the following week
B14: Identify people responsible for each activity
B15: Estimate the hours needed for the activity
A19: PROJECT NUMBER | B19: 9
A20: PROJECT NAME | B20: Room Booking Portal
A21: PROJECT MENTOR (sponsor) | B21: Santhosh
A22: TEAM MEMBERS | B22: Harshit Singh Mehta
B23: Haaris Mohammed Iqbal
B24: Ishaan Shiv Kumar
B25: Mahanth Reddy
B26: Chanakya Manikanta Reddy Arumalla

Sheet Status
A1: =(Instructions!A19) -> PROJECT NUMBER | B1: =(Instructions!B19) -> 9
A2: =(Instructions!A20) -> PROJECT NAME | B2: =(Instructions!B20) -> Room Booking Portal
A3: =(Instructions!A21) -> PROJECT MENTOR (sponsor) | B3: =(Instructions!B21) -> Santhosh
A5: Activity Name | B5: Type | C5: Responsible | D5: Estimated Team Hours | E5: Actual Hours | F5: Status | G5: Comments | H5: Estimation error | I5: Estimation error %
A6: See Instructions sheet for usage
A7: Week 1 (January 16- January 21) | H7: =IF(OR(D7="",E7=""),"",D7-E7) | I7: =IF(OR(H7="",E7=0),"",ABS(H7)/E7*100)
A8: Fix meeting with client | B8: Coordination | C8: Harshit | D8: 0.5 | E8: 0.4 | F8: Done | H8: =IF(OR(D8="",E8=""),"",D8-E8) -> 0.1 | I8: =IF(OR(H8="",E8=0),"",ABS(H8)/E8*100) -> 25
A9: Discuss alternate stacks | B9: Preparation | C9: Mahanth | D9: 1 | E9: 1 | F9: Done | G9: Discussed possibility of using a JavaScript stack instead of PHP | H9: =IF(OR(D9="",E9=""),"",D9-E9) -> 0 | I9: =IF(OR(H9="",E9=0),"",ABS(H9)/E9*100) -> 0
A10: Team Meeting | B10: Coordination | C10: Haaris | D10: 2 | E10: 1.5 | F10: Done | G10: Discussed questions to ask client | H10: =IF(OR(D10="",E10=""),"",D10-E10) -> 0.5 | I10: =IF(OR(H10="",E10=0),"",ABS(H10)/E10*100) -> 33.333333
A11: Client meeting | B11: Coordination | C11: - | D11: 1.5 | E11: 1 | F11: Done | H11: =IF(OR(D11="",E11=""),"",D11-E11) -> 0.5 | I11: =IF(OR(H11="",E11=0),"",ABS(H11)/E11*100) -> 50
A12: Set roles | B12: Preparation | C12: Harshit | D12: 1 | E12: 1 | F12: Done | H12: =IF(OR(D12="",E12=""),"",D12-E12) -> 0 | I12: =IF(OR(H12="",E12=0),"",ABS(H12)/E12*100) -> 0
A13: Project synopsis writeup | B13: Documentation | C13: Chanakya | D13: 1.5 | E13: 2 | F13: Done | H13: =IF(OR(D13="",E13=""),"",D13-E13) -> -0.5 | I13: =IF(OR(H13="",E13=0),"",ABS(H13)/E13*100) -> 25
A14: Week 2 (January 22 - January 28) | H14: =IF(OR(D14="",E14=""),"",D14-E14) | I14: =IF(OR(H14="",E14=0),"",ABS(H14)/E14*100)
A15: Backend Demo | B15: Preparation | C15: Ishaan, Haaris, Chanakya | D15: 6 | E15: 7 | F15: Done | H15: =IF(OR(D15="",E15=""),"",D15-E15) -> -1 | I15: =IF(OR(H15="",E15=0),"",ABS(H15)/E15*100) -> 14.285714
A16: Frontend Demo | B16: Preparation | C16: Harshit, Mahanth | D16: 5 | E16: 4 | F16: Done | H16: =IF(OR(D16="",E16=""),"",D16-E16) -> 1 | I16: =IF(OR(H16="",E16=0),"",ABS(H16)/E16*100) -> 25
A17: Team Meeting | B17: Coordination | C17: Mahanth, Chanakya | D17: 1 | E17: 1.5 | F17: Done | G17: Discussed and tested prototypes to show to client in meet | H17: =IF(OR(D17="",E17=""),"",D17-E17) -> -0.5 | I17: =IF(OR(H17="",E17=0),"",ABS(H17)/E17*100) -> 33.333333
A18: Client Meeting | B18: Coordination | C18: - | D18: 1 | E18: 1 | F18: Done | G18: Changed frequency of meeting to biweekly | H18: =IF(OR(D18="",E18=""),"",D18-E18) -> 0 | I18: =IF(OR(H18="",E18=0),"",ABS(H18)/E18*100) -> 0
A19: Week 3 (January 29 - February 4) | H19: =IF(OR(D19="",E19=""),"",D19-E19) | I19: =IF(OR(H19="",E19=0),"",ABS(H19)/E19*100)
A20: Backend Setup | B20: Development | C20: Ishaan, Mahanth, Chanakya | D20: 2 | E20: 2.5 | F20: Done | H20: =IF(OR(D20="",E20=""),"",D20-E20) -> -0.5 | I20: =IF(OR(H20="",E20=0),"",ABS(H20)/E20*100) -> 20
A21: Week 4 (February 5 - February 11) | H21: =IF(OR(D21="",E21=""),"",D21-E21) | I21: =IF(OR(H21="",E21=0),"",ABS(H21)/E21*100)
A22: Status Tracker | B22: Documentation | C22: Haaris | D22: 1 | E22: 1 | F22: Done | H22: =IF(OR(D22="",E22=""),"",D22-E22) -> 0 | I22: =IF(OR(H22="",E22=0),"",ABS(H22)/E22*100) -> 0
A23: Requirements Document | B23: Testing | C23: Harshit | D23: 1 | E23: 1 | F23: Done | H23: =IF(OR(D23="",E23=""),"",D23-E23) -> 0 | I23: =IF(OR(H23="",E23=0),"",ABS(H23)/E23*100) -> 0
A24: Week 5 (February 12 - February 18) | H24: =IF(OR(D24="",E24=""),"",D24-E24) | I24: =IF(OR(H24="",E24=0),"",ABS(H24)/E24*100)
A25: Status Tracker | B25: Documentation | C25: Mahanth, Chanakya | D25: 1 | E25: 1 | F25: Done | H25: =IF(OR(D25="",E25=""),"",D25-E25) -> 0 | I25: =IF(OR(H25="",E25=0),"",ABS(H25)/E25*100) -> 0
A26: project plan | B26: Documentation | C26: Harshit,Haaris,Ishaan | D26: 2 | E26: 2 | F26: Done | H26: =IF(OR(D26="",E26=""),"",D26-E26) -> 0 | I26: =IF(OR(H26="",E26=0),"",ABS(H26)/E26*100) -> 0
A27: Team Meeting | B27: Coordination | C27: Ishaan, Haaris, Chanakya | D27: 1 | E27: 1 | F27: Done | H27: =IF(OR(D27="",E27=""),"",D27-E27) -> 0 | I27: =IF(OR(H27="",E27=0),"",ABS(H27)/E27*100) -> 0
A28: Week 6 (February 19 - February 25) | H28: =IF(OR(D28="",E28=""),"",D28-E28) | I28: =IF(OR(H28="",E28=0),"",ABS(H28)/E28*100)
A29: Software Requirements specifications | B29: Documentation | C29: Harshit, Mahanth,Chanakya | D29: 2 | E29: 2 | F29: Done | H29: =IF(OR(D29="",E29=""),"",D29-E29) -> 0 | I29: =IF(OR(H29="",E29=0),"",ABS(H29)/E29*100) -> 0
A30: Client meeting | B30: Coordination | C30: Ishaan,Haaris | D30: 1 | E30: 1 | F30: Done | H30: =IF(OR(D30="",E30=""),"",D30-E30) -> 0 | I30: =IF(OR(H30="",E30=0),"",ABS(H30)/E30*100) -> 0
A31: Status Tracker | B31: Documentation | C31: Harshit | D31: 1 | E31: 1 | F31: Done | H31: =IF(OR(D32="",E32=""),"",D32-E32) | I31: =IF(OR(H31="",E32=0),"",ABS(H31)/E32*100)
A32: Week 7 (February 26 - March 4) | H32: =IF(OR(D33="",E33=""),"",D33-E33) -> 0.5 | I32: =IF(OR(H32="",E33=0),"",ABS(H32)/E33*100) -> 25
A33: Test plan | B33: Documentation | C33: Mahanth, Ishaan | D33: 2.5 | E33: 2 | F33: Done | H33: =IF(OR(D34="",E34=""),"",D34-E34) -> 0 | I33: =IF(OR(H33="",E34=0),"",ABS(H33)/E34*100) -> 0
A34: Team Meeting | B34: Coordination | C34: Harshit,Haaris | D34: 1 | E34: 1 | F34: Done | H34: =IF(OR(D38="",E38=""),"",D38-E38) | I34: =IF(OR(H34="",E38=0),"",ABS(H34)/E38*100)
A35: Frontend Development started | B35: Preparation | C35: Harshit,Haaris | D35: 3 | E35: 2.5 | F35: Done | H35: =IF(OR(D36="",E36=""),"",D36-E36) -> 0.5 | I35: =IF(OR(H35="",E36=0),"",ABS(H35)/E36*100) -> 16.666667
A36: Backend Develpoment Started | B36: Preparation | C36: Ishaan, Mahanth, Chanakya | D36: 3.5 | E36: 3 | F36: Done | I36: =IF(OR(#REF!="",#REF!=0),"",ABS(#REF!)/#REF!*100) -> #REF!
A37: Status Tracker | B37: Documentation | C37: Mahanth | D37: 1 | E37: 1 | F37: Done | H37: =IF(OR(#REF!="",#REF!=""),"",#REF!-#REF!) -> #REF! | I37: =IF(OR(H37="",#REF!=0),"",ABS(H37)/#REF!*100) -> #REF!
A38: Week 9 (March 5 - March 11) | H38: =IF(OR(#REF!="",#REF!=""),"",#REF!-#REF!) -> #REF! | I38: =IF(OR(H38="",#REF!=0),"",ABS(H38)/#REF!*100) -> #REF!
A39: Pushed R1 Frontend | B39: Development | C39: Haaris | D39: 6 | E39: 7 | F39: Done | H39: =IF(OR(D39="",E39=""),"",D39-E39) -> -1 | I39: =IF(OR(H39="",E39=0),"",ABS(H39)/E39*100) -> 14.285714
A40: Pushed R1 Backend | B40: Development | C40: Mahanth, Chanakya, Ishaan | D40: 8 | E40: 9 | F40: Done | H40: =IF(OR(D40="",E40=""),"",D40-E40) -> -1 | I40: =IF(OR(H40="",E40=0),"",ABS(H40)/E40*100) -> 11.111111
A41: Week 10 (March 12 - March 19) | H41: =IF(OR(D41="",E41=""),"",D41-E41) | I41: =IF(OR(H41="",E41=0),"",ABS(H41)/E41*100)
...
